Workbook

Sheet 記入用
A1: 化合物構造をここに添付
E2: Note | F2: looks | H2: HRMS | I2: Formula | J2: MS calcd | K2: OR
F3: white solid | I3: C42H65FO9 | J3: 755.4510 | K3: relative-OR/conc | L3: Solvent/Temp
E4: Solvent for 1H | F4: Solvent for 13C | H4: Ionization | I4: HRMS(ESI): m/z calcd for | J4: MS found | K4: -29.5 | L4: CHCl3
E5: CDCl3 | F5: CDCl3 | H5: ESI | I5: M+Na | J5: 755.4496 | K5: 0.25 | L5: 29
D6: 1H以外 の時、H数 を書く | J6: 1C以外 の時、C数 を書く | P6: 1F以外 の時、F数 を書く
C7: 化学シフト, J値（貼り付ける） | D7: 重複 | E7: 帰属 | F7: 1H数 | I7: シフト（貼り付ける） | J7: 重複 | K7: 帰属 | L7: 13C数 | O7: シフト（貼り付ける） | P7: 重複 | Q7: 帰属 | R7: 19F数
B8: 1Hシフト & J値 → → 書き込む → → | C8: 7.38–7.26 (m, 20H) | D8: 20 | E8: Bn CH | F8: =IF(D8="",IF(C8="","",1),D8) -> 20 | H8: 13Cシフト & 個数 → → 書き込む → → | I8: 170.29 | K8: Ac | L8: =IF(J8="",IF(I8="","",1),J8) -> 1 | N8: 19Fシフト & 個数 → → 書き込む → → | R8: =IF(P8="",IF(O8="","",1),P8)
C9: 5.14 (dd, J = 34.3, 8.5 Hz, 1H) | E9: 6 | F9: =IF(D9="",IF(C9="","",1),D9) -> 1 | I9: 170.22 | K9: Ac | L9: =IF(J9="",IF(I9="","",1),J9) -> 1 | R9: =IF(P9="",IF(O9="","",1),P9)
C10: 5.11 (dd, J = 9.2, 9.0 Hz, 1H) | E10: 3' | F10: =IF(D10="",IF(C10="","",1),D10) -> 1 | I10: 156.57 | K10: 7 | L10: =IF(J10="",IF(I10="","",1),J10) -> 1 | R10: =IF(P10="",IF(O10="","",1),P10)
C11: 4.99 (ddd, J = 10.3, 9.2, 5.6 Hz, 1H) | E11: 4' | F11: =IF(D11="",IF(C11="","",1),D11) -> 1 | I11: 138.67 | K11: Bn C | L11: =IF(J11="",IF(I11="","",1),J11) -> 1 | R11: =IF(P11="",IF(O11="","",1),P11)
C12: 4.94 (m, 2H) | D12: 2 | E12: Bn (A,B) | F12: =IF(D12="",IF(C12="","",1),D12) -> 2 | I12: 138.48 | K12: Bn C | L12: =IF(J12="",IF(I12="","",1),J12) -> 1 | R12: =IF(P12="",IF(O12="","",1),P12)
C13: 4.89 (d, J = 10.8 Hz, 1H) | E13: BnC | F13: =IF(D13="",IF(C13="","",1),D13) -> 1 | I13: 137.88 | K13: Bn C | L13: =IF(J13="",IF(I13="","",1),J13) -> 1 | R13: =IF(P13="",IF(O13="","",1),P13)
C14: 4.82 (d, J = 10.8 Hz, 1H) | E14: BnC | F14: =IF(D14="",IF(C14="","",1),D14) -> 1 | I14: 137.33 | K14: Bn C | L14: =IF(J14="",IF(I14="","",1),J14) -> 1 | R14: =IF(P14="",IF(O14="","",1),P14)
C15: 4.73 (d, J = 11.0 Hz, 1H) | E15: BnA | F15: =IF(D15="",IF(C15="","",1),D15) -> 1 | I15: 128.96 | J15: 2 | K15: Bn CH | L15: =IF(J15="",IF(I15="","",1),J15) -> 2 | R15: =IF(P15="",IF(O15="","",1),P15)
C16: 4.72 (d, J = 10.2 Hz, 1H) | E16: BnD | F16: =IF(D16="",IF(C16="","",1),D16) -> 1 | I16: 128.59 | J16: 2 | K16: Bn CH | L16: =IF(J16="",IF(I16="","",1),J16) -> 2 | R16: =IF(P16="",IF(O16="","",1),P16)
C17: 4.69 (d, J = 10.2 Hz, 1H) | E17: BnD | F17: =IF(D17="",IF(C17="","",1),D17) -> 1 | I17: 128.51 | J17: 2 | K17: Bn CH | L17: =IF(J17="",IF(I17="","",1),J17) -> 2 | R17: =IF(P17="",IF(O17="","",1),P17)
C18: 4.59 (d, J = 11.8 Hz, 1H) | E18: BnB | F18: =IF(D18="",IF(C18="","",1),D18) -> 1 | I18: 128.45 | J18: 2 | K18: Bn CH | L18: =IF(J18="",IF(I18="","",1),J18) -> 2 | R18: =IF(P18="",IF(O18="","",1),P18)
C19: 4.56 (d, J = 7.8 Hz, 1H) | E19: 1 | F19: =IF(D19="",IF(C19="","",1),D19) -> 1 | I19: 128.42 | J19: 2 | K19: Bn CH | L19: =IF(J19="",IF(I19="","",1),J19) -> 2 | R19: =IF(P19="",IF(O19="","",1),P19)
C20: 4.34 (dd, J = 9.2, 8.5 Hz, 1H) | E20: 5 | F20: =IF(D20="",IF(C20="","",1),D20) -> 1 | I20: 128.22 | J20: 2 | K20: Bn CH | L20: =IF(J20="",IF(I20="","",1),J20) -> 2 | R20: =IF(P20="",IF(O20="","",1),P20)
C21: 4.21 (dd, J = 9.1, 9.0 Hz, 1H) | E21: 2' | F21: =IF(D21="",IF(C21="","",1),D21) -> 1 | I21: 128.06 | J21: 2 | K21: Bn CH | L21: =IF(J21="",IF(I21="","",1),J21) -> 2 | R21: =IF(P21="",IF(O21="","",1),P21)
C22: 4.07 (dd, J = 11.1, 5.6 Hz, 1H) | E22: 5' eq | F22: =IF(D22="",IF(C22="","",1),D22) -> 1 | I22: 128.00 | K22: Bn CH | L22: =IF(J22="",IF(I22="","",1),J22) -> 1 | R22: =IF(P22="",IF(O22="","",1),P22)
C23: 3.73 (dd, J = 24.2, 9.1 Hz, 1H) | E23: 1' | F23: =IF(D23="",IF(C23="","",1),D23) -> 1 | I23: 127.98 | K23: Bn CH | L23: =IF(J23="",IF(I23="","",1),J23) -> 1 | R23: =IF(P23="",IF(O23="","",1),P23)
C24: 3.68 (dd, J = 9.3, 9.1 Hz, 1H) | E24: 3 | F24: =IF(D24="",IF(C24="","",1),D24) -> 1 | I24: 127.96 | J24: 2 | K24: Bn CH | L24: =IF(J24="",IF(I24="","",1),J24) -> 2 | R24: =IF(P24="",IF(O24="","",1),P24)
C25: 3.50 (dd, J = 9.2, 7.8 Hz, 1H) | E25: 2 | F25: =IF(D25="",IF(C25="","",1),D25) -> 1 | I25: 127.77 | J25: 2 | K25: Bn CH | L25: =IF(J25="",IF(I25="","",1),J25) -> 2 | R25: =IF(P25="",IF(O25="","",1),P25)
C26: 3.42 (dd, J = 11.1, 10.3 Hz, 1H) | E26: 5' ax | F26: =IF(D26="",IF(C26="","",1),D26) -> 1 | I26: 111.37 | K26: 6 | L26: =IF(J26="",IF(I26="","",1),J26) -> 1 | R26: =IF(P26="",IF(O26="","",1),P26)
C27: 3.37 (dd, J = 9.2, 9.1 Hz, 1H) | E27: 4 | F27: =IF(D27="",IF(C27="","",1),D27) -> 1 | I27: 102.73 | K27: 1 | L27: =IF(J27="",IF(I27="","",1),J27) -> 1 | R27: =IF(P27="",IF(O27="","",1),P27)
C28: 2.09 (s, 3H) | D28: 3 | E28: Ac | F28: =IF(D28="",IF(C28="","",1),D28) -> 3 | I28: 84.29 | K28: 3 | L28: =IF(J28="",IF(I28="","",1),J28) -> 1 | R28: =IF(P28="",IF(O28="","",1),P28)
C29: 2.04 (s, 3H) | D29: 3 | E29: Ac | F29: =IF(D29="",IF(C29="","",1),D29) -> 3 | I29: 82.20 | K29: 2 | L29: =IF(J29="",IF(I29="","",1),J29) -> 1 | R29: =IF(P29="",IF(O29="","",1),P29)
C30: 1.11–1.07 (m, 21H) | D30: 21 | E30: TIPS | F30: =IF(D30="",IF(C30="","",1),D30) -> 21 | I30: 81.55 | K30: 4 | L30: =IF(J30="",IF(I30="","",1),J30) -> 1 | R30: =IF(P30="",IF(O30="","",1),P30)
F31: =IF(D31="",IF(C31="","",1),D31) | I31: 81.10 | K31: 1' | L31: =IF(J31="",IF(I31="","",1),J31) -> 1 | R31: =IF(P31="",IF(O31="","",1),P31)
F32: =IF(D32="",IF(C32="","",1),D32) | I32: 77.08 | K32: 3' | L32: =IF(J32="",IF(I32="","",1),J32) -> 1 | R32: =IF(P32="",IF(O32="","",1),P32)
F33: =IF(D33="",IF(C33="","",1),D33) | I33: 76.08 | K33: BnCH2 | L33: =IF(J33="",IF(I33="","",1),J33) -> 1 | R33: =IF(P33="",IF(O33="","",1),P33)
F34: =IF(D34="",IF(C34="","",1),D34) | I34: 75.60 | K34: BnCH2 | L34: =IF(J34="",IF(I34="","",1),J34) -> 1 | R34: =IF(P34="",IF(O34="","",1),P34)
F35: =IF(D35="",IF(C35="","",1),D35) | I35: 75.09 | K35: BnCH2 | L35: =IF(J35="",IF(I35="","",1),J35) -> 1 | R35: =IF(P35="",IF(O35="","",1),P35)
F36: =IF(D36="",IF(C36="","",1),D36) | I36: 71.44 | K36: BnCH2 | L36: =IF(J36="",IF(I36="","",1),J36) -> 1 | R36: =IF(P36="",IF(O36="","",1),P36)
F37: =IF(D37="",IF(C37="","",1),D37) | I37: 69.76 | K37: 4' | L37: =IF(J37="",IF(I37="","",1),J37) -> 1 | R37: =IF(P37="",IF(O37="","",1),P37)
F38: =IF(D38="",IF(C38="","",1),D38) | I38: 69.39 | K38: 2' | L38: =IF(J38="",IF(I38="","",1),J38) -> 1 | R38: =IF(P38="",IF(O38="","",1),P38)
F39: =IF(D39="",IF(C39="","",1),D39) | I39: 69.21 | K39: 5 | L39: =IF(J39="",IF(I39="","",1),J39) -> 1 | R39: =IF(P39="",IF(O39="","",1),P39)
F40: =IF(D40="",IF(C40="","",1),D40) | I40: 66.89 | K40: 5' | L40: =IF(J40="",IF(I40="","",1),J40) -> 1 | R40: =IF(P40="",IF(O40="","",1),P40)
...

Sheet コピー用
C2: ↓コピー範囲↓
B3: 1Hシフト & J値 | C3: ="1H NMR (500 MHz, "&記入用!E5&")" -> 1H NMR (500 MHz, CDCl3) | N3: =C3 -> 1H NMR (500 MHz, CDCl3) | O3: {=": δ "&_xlfn.TEXTJOIN(", ", TRUE, _xlfn._xlws.FILTER(C4:C45, C4:C45<>""))&"."} -> : δ 7.38–7.26 (m, 20H), 5.14 (dd, J = 34.3, 8.5 Hz, 1H), 5.11 (dd, J = 9.2, 9.0 Hz, 1H), 4.99 (ddd, J = 10.3, 9.2, 5.6 Hz, 1H), 4.94 (m, 2H), 4.89 (d, J = 10.8 Hz, 1H), 4.82 (d, J = 10.8 Hz, 1H), 4.73 (d, J = 11.0 Hz, 1H), 4.72 (d, J = 10.2 Hz, 1H), 4.69 (d, J = 10.2 Hz, 1H), 4.59 (d, J = 11.8 Hz, 1H), 4.56 (d, J = 7.8 Hz, 1H), 4.34 (dd, J = 9.2, 8.5 Hz, 1H), 4.21 (dd, J = 9.1, 9.0 Hz, 1H), 4.07 (dd, J = 11.1, 5.6 Hz, 1H), 3.73 (dd, J = 24.2, 9.1 Hz, 1H), 3.68 (dd, J = 9.3, 9.1 Hz, 1H), 3.50 (dd, J = 9.2, 7.8 Hz, 1H), 3.42 (dd, J = 11.1, 10.3 Hz, 1H), 3.37 (dd, J = 9.2, 9.1 Hz, 1H), 2.09 (s, 3H), 2.04 (s, 3H), 1.11–1.07 (m, 21H).
C4: =IF(記入用!C8="","",記入用!C8) -> 7.38–7.26 (m, 20H) | N4: =C46 -> 13C{1H} NMR (126 MHz, CDCl3) | O4: =": δ "&_xlfn.TEXTJOIN(", ", TRUE, _xlfn.BYROW(C47:C98, _xlfn.LAMBDA(_xlpm.r, _xlfn.TEXTJOIN("", TRUE, _xlpm.r))))&"." -> : δ 170.29, 170.22, 156.57, 138.67, 138.48, 137.88, 137.33, 128.96 (2C), 128.59 (2C), 128.51 (2C), 128.45 (2C), 128.42 (2C), 128.22 (2C), 128.06 (2C), 128.00, 127.98, 127.96 (2C), 127.77 (2C), 111.37, 102.73, 84.29, 82.20, 81.55, 81.10, 77.08, 76.08, 75.60, 75.09, 71.44, 69.76, 69.39, 69.21, 66.89, 21.27, 20.90, 18.35 (3C), 18.18 (3C), 13.39 (3C).
C5: =IF(記入用!C9="","",記入用!C9) -> 5.14 (dd, J = 34.3, 8.5 Hz, 1H) | N5: =C99 -> 19F NMR (476 MHz, CDCl3) | O5: {=": δ "&_xlfn.TEXTJOIN(", ", TRUE, _xlfn._xlws.FILTER(C100:C104, C100:C104<>""))&"."} -> #VALUE!
C6: =IF(記入用!C10="","",記入用!C10) -> 5.11 (dd, J = 9.2, 9.0 Hz, 1H) | N6: ="HRMS("&記入用!H5&")" -> HRMS(ESI) | O6: =": m/z ["&記入用!I5&"]+ calcd for "&記入用!I3&" "&記入用!J3&", found "&記入用!J5&"." -> : m/z [M+Na]+ calcd for C42H65FO9 755.4510, found 755.4496.
C7: =IF(記入用!C11="","",記入用!C11) -> 4.99 (ddd, J = 10.3, 9.2, 5.6 Hz, 1H) | N7: ="[α]D"&記入用!L5 -> [α]D29 | O7: =" "&記入用!K4&" (c = "&記入用!K5&", "&記入用!L4&")"&"." -> -29.5 (c = 0.25, CHCl3).
C8: =IF(記入用!C12="","",記入用!C12) -> 4.94 (m, 2H)
C9: =IF(記入用!C13="","",記入用!C13) -> 4.89 (d, J = 10.8 Hz, 1H)
C10: =IF(記入用!C14="","",記入用!C14) -> 4.82 (d, J = 10.8 Hz, 1H)
C11: =IF(記入用!C15="","",記入用!C15) -> 4.73 (d, J = 11.0 Hz, 1H)
C12: =IF(記入用!C16="","",記入用!C16) -> 4.72 (d, J = 10.2 Hz, 1H)
C13: =IF(記入用!C17="","",記入用!C17) -> 4.69 (d, J = 10.2 Hz, 1H)
C14: =IF(記入用!C18="","",記入用!C18) -> 4.59 (d, J = 11.8 Hz, 1H)
C15: =IF(記入用!C19="","",記入用!C19) -> 4.56 (d, J = 7.8 Hz, 1H)
C16: =IF(記入用!C20="","",記入用!C20) -> 4.34 (dd, J = 9.2, 8.5 Hz, 1H)
C17: =IF(記入用!C21="","",記入用!C21) -> 4.21 (dd, J = 9.1, 9.0 Hz, 1H)
C18: =IF(記入用!C22="","",記入用!C22) -> 4.07 (dd, J = 11.1, 5.6 Hz, 1H)
C19: =IF(記入用!C23="","",記入用!C23) -> 3.73 (dd, J = 24.2, 9.1 Hz, 1H)
... C43: =IF(記入用!C47="","",記入用!C47)
C44: =IF(記入用!C58="","",記入用!C58)
C45: =IF(記入用!C59="","",記入用!C59)
B46: 13Cシフト & 個数 | C46: ="13C{1H} NMR (126 MHz, "&記入用!F5&")" -> 13C{1H} NMR (126 MHz, CDCl3)
C47: =IF(記入用!I8="","",記入用!I8&IF(記入用!J8="",""," ("&記入用!J8&"C)")) -> 170.29
C48: =IF(記入用!I9="","",記入用!I9&IF(記入用!J9="",""," ("&記入用!J9&"C)")) -> 170.22
C49: =IF(記入用!I10="","",記入用!I10&IF(記入用!J10="",""," ("&記入用!J10&"C)")) -> 156.57
C50: =IF(記入用!I11="","",記入用!I11&IF(記入用!J11="",""," ("&記入用!J11&"C)")) -> 138.67
C51: =IF(記入用!I12="","",記入用!I12&IF(記入用!J12="",""," ("&記入用!J12&"C)")) -> 138.48
C52: =IF(記入用!I13="","",記入用!I13&IF(記入用!J13="",""," ("&記入用!J13&"C)")) -> 137.88
C53: =IF(記入用!I14="","",記入用!I14&IF(記入用!J14="",""," ("&記入用!J14&"C)")) -> 137.33
C54: =IF(記入用!I15="","",記入用!I15&IF(記入用!J15="",""," ("&記入用!J15&"C)")) -> 128.96 (2C)
C55: =IF(記入用!I16="","",記入用!I16&IF(記入用!J16="",""," ("&記入用!J16&"C)")) -> 128.59 (2C)
C56: =IF(記入用!I17="","",記入用!I17&IF(記入用!J17="",""," ("&記入用!J17&"C)")) -> 128.51 (2C)
C57: =IF(記入用!I18="","",記入用!I18&IF(記入用!J18="",""," ("&記入用!J18&"C)")) -> 128.45 (2C)
C58: =IF(記入用!I19="","",記入用!I19&IF(記入用!J19="",""," ("&記入用!J19&"C)")) -> 128.42 (2C)
... C98: =IF(記入用!I59="","",記入用!I59&IF(記入用!J59="",""," ("&記入用!J59&"C)"))
B99: 19Fシフト & 個数 | C99: ="19F NMR (476 MHz, "&記入用!E5&")" -> 19F NMR (476 MHz, CDCl3)
C100: =IF(記入用!O8="","",記入用!O8)
C101: =IF(記入用!O9="","",記入用!O9)
C102: =IF(記入用!O10="","",記入用!O10)
C103: =IF(記入用!O11="","",記入用!O11)
...

Sheet Python
A1: =コピー用!N3 -> 1H NMR (500 MHz, CDCl3) | B1: =コピー用!O3 -> : δ 7.38–7.26 (m, 20H), 5.14 (dd, J = 34.3, 8.5 Hz, 1H), 5.11 (dd, J = 9.2, 9.0 Hz, 1H), 4.99 (ddd, J = 10.3, 9.2, 5.6 Hz, 1H), 4.94 (m, 2H), 4.89 (d, J = 10.8 Hz, 1H), 4.82 (d, J = 10.8 Hz, 1H), 4.73 (d, J = 11.0 Hz, 1H), 4.72 (d, J = 10.2 Hz, 1H), 4.69 (d, J = 10.2 Hz, 1H), 4.59 (d, J = 11.8 Hz, 1H), 4.56 (d, J = 7.8 Hz, 1H), 4.34 (dd, J = 9.2, 8.5 Hz, 1H), 4.21 (dd, J = 9.1, 9.0 Hz, 1H), 4.07 (dd, J = 11.1, 5.6 Hz, 1H), 3.73 (dd, J = 24.2, 9.1 Hz, 1H), 3.68 (dd, J = 9.3, 9.1 Hz, 1H), 3.50 (dd, J = 9.2, 7.8 Hz, 1H), 3.42 (dd, J = 11.1, 10.3 Hz, 1H), 3.37 (dd, J = 9.2, 9.1 Hz, 1H), 2.09 (s, 3H), 2.04 (s, 3H), 1.11–1.07 (m, 21H).
A2: =コピー用!N4 -> 13C{1H} NMR (126 MHz, CDCl3) | B2: =コピー用!O4 -> : δ 170.29, 170.22, 156.57, 138.67, 138.48, 137.88, 137.33, 128.96 (2C), 128.59 (2C), 128.51 (2C), 128.45 (2C), 128.42 (2C), 128.22 (2C), 128.06 (2C), 128.00, 127.98, 127.96 (2C), 127.77 (2C), 111.37, 102.73, 84.29, 82.20, 81.55, 81.10, 77.08, 76.08, 75.60, 75.09, 71.44, 69.76, 69.39, 69.21, 66.89, 21.27, 20.90, 18.35 (3C), 18.18 (3C), 13.39 (3C).
A3: =コピー用!N5 -> 19F NMR (476 MHz, CDCl3) | B3: =コピー用!O5 -> #VALUE!
A4: =コピー用!N6 -> HRMS(ESI) | B4: =コピー用!O6 -> : m/z [M+Na]+ calcd for C42H65FO9 755.4510, found 755.4496.
A5: =コピー用!N7 -> [α]D29 | B5: =コピー用!O7 -> -29.5 (c = 0.25, CHCl3).
